В Java исключения обрабатываются с использованием конструкций `try`, `catch`, `finally` и `throw`. Эти конструкции позволяют перехватывать ошибки (исключения), которые могут возникнуть во время выполнения программы, и обрабатывать их соответствующим образом.

### Основные конструкции для обработки исключений

1. **try**: Блок кода, в котором могут возникнуть исключения.
2. **catch**: Блок кода, который обрабатывает исключение, если оно возникает в блоке `try`.
3. **finally**: Блок кода, который выполняется в любом случае после выполнения блоков `try` и `catch`.
4. **throw**: Используется для явного создания исключения.

### Пример обработки исключений

Рассмотрим пример, где мы делим одно число на другое, и возможное исключение — деление на ноль — обрабатывается с помощью `try` и `catch`.

```
public class ExceptionHandlingExample {
    public static void main(String[] args) {
        try {
            int numerator = 10;
            int denominator = 0;
            int result = numerator / denominator; // Это вызовет ArithmeticException
            System.out.println("Result: " + result);
        } catch (ArithmeticException e) {
            System.out.println("Error: Cannot divide by zero.");
        } finally {
            System.out.println("This block is always executed.");
        }
    }
}
```

### Объяснение кода

1. **try**: Внутри блока `try` мы пытаемся выполнить операцию деления. Если `denominator` равен нулю, произойдёт исключение `ArithmeticException`.
2. **catch**: Если в блоке `try` возникает исключение, выполнение переходит в соответствующий блок `catch`, где мы обрабатываем это исключение.
3. **finally**: Независимо от того, возникло исключение или нет, блок `finally` будет выполнен. Это полезно для освобождения ресурсов, закрытия файлов и других операций очистки.

### Пример с несколькими блоками `catch`

Вы можете использовать несколько блоков `catch` для обработки различных типов исключений.

```
public class MultipleCatchExample {
    public static void main(String[] args) {
        try {
            int[] array = new int[5];
            array[10] = 50; // Это вызовет ArrayIndexOutOfBoundsException
            int numerator = 10;
            int denominator = 0;
            int result = numerator / denominator; // Это вызовет ArithmeticException
            System.out.println("Result: " + result);
        } catch (ArrayIndexOutOfBoundsException e) {
            System.out.println("Error: Array index out of bounds.");
        } catch (ArithmeticException e) {
            System.out.println("Error: Cannot divide by zero.");
        } finally {
            System.out.println("This block is always executed.");
        }
    }
}
```

### Явное создание исключений с помощью `throw`

Вы можете явным образом создать исключение с помощью ключевого слова `throw`.

```
public class ThrowExample {
    public static void main(String[] args) {
        try {
            validateAge(15);
        } catch (IllegalArgumentException e) {
            System.out.println("Exception: " + e.getMessage());
        }
    }

    static void validateAge(int age) {
        if (age < 18) {
            throw new IllegalArgumentException("Age must be 18 or above.");
        } else {
            System.out.println("Age is valid.");
        }
    }
}
```

### Объяснение кода

1. **throw**: В методе `validateAge` мы проверяем возраст и создаём исключение `IllegalArgumentException`, если возраст меньше 18.
2. **catch**: В методе `main` мы вызываем `validateAge` и перехватываем исключение, если оно возникает, выводя соответствующее сообщение.

### Заключение

Обработка исключений в Java позволяет вам управлять ошибками в программе, делая её более надёжной и устойчивой к неожиданным ситуациям. Использование блоков `try`, `catch`, `finally` и ключевого слова `throw` даёт возможность гибко и эффективно обрабатывать ошибки.